<?xml version="1.0"?>
<robot name="fancy_car">
  
  <!-- Car Base -->
  <link name="base_link">
    <visual>
      <geometry>
        <box size="2.0 1.0 0.5"/> <!-- Body of the Car -->
      </geometry>
      <material name="red">
        <color rgba="1.0 0.0 0.0 1.0"/>
      </material>
    </visual>
    <collision>
      <geometry>
        <box size="2.0 1.0 0.5"/>
      </geometry>
    </collision>
    <inertial>
      <mass value="10.0"/>
      <origin xyz="0 0 0"/>
      <inertia ixx="0.1" iyy="0.1" izz="0.1"/>
    </inertial>
  </link>

  <!-- Wheels -->
  <link name="wheel_fl">
    <visual>
      <geometry>
        <cylinder length="0.2" radius="0.3"/>
      </geometry>
      <material name="black">
        <color rgba="0.0 0.0 0.0 1.0"/>
      </material>
    </visual>
    <inertial>
      <mass value="2.0"/>
      <inertia ixx="0.001" ixy="0.0" ixz="0.0"
              iyy="0.001" iyz="0.0"
              izz="0.002"/>
      </inertial>
  </link>

  <link name="wheel_fr">
    <visual>
      <geometry>
        <cylinder length="0.2" radius="0.3"/>
      </geometry>
      <material name="black">
        <color rgba="0.0 0.0 0.0 1.0"/>
      </material>
    </visual>
    <inertial>
      <mass value="2.0"/>
      <inertia ixx="0.001" ixy="0.0" ixz="0.0"
              iyy="0.001" iyz="0.0"
              izz="0.002"/>
      </inertial>
  </link>

  <link name="wheel_rl">
    <visual>
      <geometry>
        <cylinder length="0.2" radius="0.3"/>
      </geometry>
      <material name="black">
        <color rgba="0.0 0.0 0.0 1.0"/>
      </material>
    </visual>
    <inertial>
      <mass value="2.0"/>
      <inertia ixx="0.001" ixy="0.0" ixz="0.0"
              iyy="0.001" iyz="0.0"
              izz="0.002"/>
      </inertial> 
  </link>

  <link name="wheel_rr">
    <visual>
      <geometry>
        <cylinder length="0.2" radius="0.3"/>
      </geometry>
      <material name="black">
        <color rgba="0.0 0.0 0.0 1.0"/>
      </material>
    </visual>
    <inertial>
      <mass value="2.0"/>
      <inertia ixx="0.001" ixy="0.0" ixz="0.0"
              iyy="0.001" iyz="0.0"
              izz="0.002"/>
      </inertial>
  </link>

  <!-- Joints -->
  <joint name="joint_fl" type="continuous">
    <parent link="base_link"/>
    <child link="wheel_fl"/>
    <origin xyz="-0.8 0.5 -0.25"/>
    <axis xyz="0 1 0"/>
  </joint>

  <joint name="joint_fr" type="continuous">
    <parent link="base_link"/>
    <child link="wheel_fr"/>
    <origin xyz="0.8 0.5 -0.25"/>
    <axis xyz="0 1 0"/>
  </joint>

  <joint name="joint_rl" type="continuous">
    <parent link="base_link"/>
    <child link="wheel_rl"/>
    <origin xyz="-0.8 -0.5 -0.25"/>
    <axis xyz="0 1 0"/>
  </joint>

  <joint name="joint_rr" type="continuous">
    <parent link="base_link"/>
    <child link="wheel_rr"/>
    <origin xyz="0.8 -0.5 -0.25"/>
    <axis xyz="0 1 0"/>
  </joint>
  <transmission name="trans_joint_fl">
        <type>transmission_interface/SimpleTransmission</type>
        <joint name="joint_fl">
            <hardwareInterface>hardware_interface/PositionJointInterface</hardwareInterface>
        </joint>
        <actuator name="joint_fl_motor">
            <hardwareInterface>hardware_interface/PositionJointInterface</hardwareInterface>
            <mechanicalReduction>1</mechanicalReduction>
        </actuator>
  </transmission>
  <transmission name="trans_joint_1">
        <type>transmission_interface/SimpleTransmission</type>
        <joint name="joint_fr">
            <hardwareInterface>hardware_interface/PositionJointInterface</hardwareInterface>
        </joint>
        <actuator name="joint_1_motor">
            <hardwareInterface>hardware_interface/PositionJointInterface</hardwareInterface>
            <mechanicalReduction>1</mechanicalReduction>
        </actuator>
  </transmission>
  <transmission name="trans_joint_2">
        <type>transmission_interface/SimpleTransmission</type>
        <joint name="joint_rl">
            <hardwareInterface>hardware_interface/PositionJointInterface</hardwareInterface>
        </joint>
        <actuator name="joint_2_motor">
            <hardwareInterface>hardware_interface/PositionJointInterface</hardwareInterface>
            <mechanicalReduction>1</mechanicalReduction>
        </actuator>
  </transmission>
  <transmission name="trans_joint_3">
        <type>transmission_interface/SimpleTransmission</type>
        <joint name="joint_rr">
            <hardwareInterface>hardware_interface/PositionJointInterface</hardwareInterface>
        </joint>
        <actuator name="joint_3_motor">
            <hardwareInterface>hardware_interface/PositionJointInterface</hardwareInterface>
            <mechanicalReduction>1</mechanicalReduction>
        </actuator>
  </transmission>
  <gazebo>
        <plugin name="gazebo_ros_control" filename="libgazebo_ros_control.so">
            <robotSimType>gazebo_ros_control/DefaultRobotHWSim</robotSimType>
            <legacyModeNS>true</legacyModeNS>
            <robotNamespace>/</robotNamespace>
        </plugin>
  </gazebo>
</robot>
