<?xml version="1.0"?>
<robot name="box_robot">
    <link name="world"/>  <!-- Explicitly define world link -->

    <link name="base_link">
        <inertial>
            <mass value="1.0"/>
            <inertia ixx="0.01" ixy="0.0" ixz="0.0" iyy="0.01" iyz="0.0" izz="0.01"/>
        </inertial>
        <visual>
            <geometry>
                <box size="0.5 0.5 0.5"/>
            </geometry>
            <material name="blue">
                <color rgba="0.0 0.0 1.0 1.0"/>
            </material>
        </visual>
        <collision>
            <geometry>
                <box size="0.5 0.5 0.5"/>
            </geometry>
        </collision>
    </link>

    <joint name="floating_joint" type="continuous">
        <parent link="world"/>
        <child link="base_link"/>
    </joint>
    <gazebo>
        <plugin name="gazebo_ros_control" filename="libgazebo_ros_control.so"/>
    </gazebo>

</robot>
